import { PromiseResult } from "./promiseResult.mjs";
import { getTimerPromise } from "./promiseHelpers.mjs";
import { Result, FailedResult, SucceededResult } from "./result.mjs";
import { pipeAsync } from "./pipeAsync.mjs";


describe("augment()", () => {

    it("if the input is an error, returns it without invoking the function", async () => {
        function step1() {
            return Promise.resolve(new FailedResult("Step 1 error."));
        }

        let numStep2Invocations = 0;
        function step2() {
            numStep2Invocations++;
            return Promise.resolve(new SucceededResult({ c: 3, d: 4 }));
        }

        const res =
            await pipeAsync(step1())
            .pipe((res) => PromiseResult.augment(step2, res))
            .end();

        expect(res).toEqual(new FailedResult("Step 1 error."));
        expect(numStep2Invocations).toEqual(0);
    });


    it("if the input is successful, invokes fn", async () => {
        function step1() {
            return Promise.resolve(new SucceededResult({ a: 1, b: 2 }));
        }

        let numStep2Invocations = 0;
        function step2(props: { b: number; }) {
            numStep2Invocations++;
            return Promise.resolve(new SucceededResult({ c: props.b + 1, d: props.b + 2 }));
        }

        const __res =
            await pipeAsync(step1())
            .pipe((res) => PromiseResult.augment(step2, res))
            .end();

        expect(numStep2Invocations).toEqual(1);
    });


    it("if the input is successful and fn errors, returns fn's error", async () => {
        function step1() {
            return Promise.resolve(new SucceededResult({ a: 1, b: 2 }));
        }

        let numStep2Invocations = 0;
        function step2(props: { b: number; }) {
            numStep2Invocations++;
            return Promise.resolve(new FailedResult("Step 2 error."));
        }

        const res =
            await pipeAsync(step1())
            .pipe((res) => PromiseResult.augment(step2, res))
            .end();

        expect(numStep2Invocations).toEqual(1);
        expect(res).toEqual(new FailedResult("Step 2 error."));
    });


    it("if the input and fn are successful, returns a successful result containing all properties", async () => {
        function step1() {
            return Promise.resolve(new SucceededResult({ a: 1, b: 2 }));
        }

        let numStep2Invocations = 0;
        function step2(props: { b: number; }) {
            numStep2Invocations++;
            return Promise.resolve(new SucceededResult({ c: props.b + 1, d: props.b + 2 }));
        }

        const res =
            await pipeAsync(step1())
            .pipe((res) => PromiseResult.augment(step2, res))
            .end();

        expect(numStep2Invocations).toEqual(1);
        expect(res).toEqual(new SucceededResult({ a: 1, b: 2, c: 3, d: 4 }));
    });


    it("properties in the original input can be reassigned", async () => {
        function step1() {
            return Promise.resolve(new SucceededResult({ a: 1, b: 2 }));
        }

        let numStep2Invocations = 0;
        function step2(props: { b: number; }) {
            numStep2Invocations++;
            return Promise.resolve(new SucceededResult({ b: 0 }));
        }

        const res =
            await pipeAsync(step1())
            .pipe((res) => PromiseResult.augment(step2, res))
            .end();

        expect(numStep2Invocations).toEqual(1);
        expect(res).toEqual(new SucceededResult({ a: 1, b: 0 }));
    });

});


describe("toPromise()", () => {
    it("when given an error result returns a rejected promise", async () => {
        const pr = Promise.resolve(new FailedResult("error message"));
        try {
            const __val = await PromiseResult.toPromise(pr);
            expect(false).toBeTruthy();
        }
        catch (error) {
            expect(error).toEqual("error message");
        }
    });


    it("when given a successful result returns a resolved promise", async () => {
        const pr = Promise.resolve(new SucceededResult("success value"));
        try {
            const val = await PromiseResult.toPromise(pr);
            expect(val).toEqual("success value");
        }
        catch (error) {
            expect(false).toBeTruthy();
        }
    });
});


describe("fromPromise()", () => {

    it("when the Promise resolves a successful Result is returned", async () => {
        const res = await PromiseResult.fromPromise(Promise.resolve(5));
        expect(res.succeeded).toBeTrue();
        expect(res.value).toEqual(5);
    });


    it("when the Promise rejects a failure Result with a string is returned", async () => {
        const res = await PromiseResult.fromPromise(Promise.reject(new Error("error message")));
        expect(res.failed).toBeTrue();
        expect(res.error).toEqual("error message");
    });

});


describe("fromPromiseWith()", () => {

    const errorMapper = (err: unknown) => {
        return typeof err === "string" ? new Error(`Error: ${err}`) : new Error("unknown error");
    };


    it("when the Promise resolves a successful Result is returned", async () => {
        const res = await PromiseResult.fromPromiseWith(Promise.resolve(19), errorMapper);
        expect(res.succeeded).toBeTrue();
        expect(res.value).toEqual(19);
    });


    it("when the Promise rejects a failure Result with a mapped value is returned", async () => {
        const res = await PromiseResult.fromPromiseWith(Promise.reject("error 37"), errorMapper);
        expect(res.failed).toBeTrue();
        expect(res.error).toBeInstanceOf(Error);
        expect(res.error!.message).toEqual("Error: error 37");
    });

});


describe("allObj()", () => {

    const opSuccessA = (): Promise<Result<string, number>> => getTimerPromise(50, new SucceededResult("hello"));
    const opSuccessB = (): Promise<Result<string[], string>> => getTimerPromise(20, new SucceededResult(["one", "two", "three"]));
    const opFailA = (): Promise<Result<number, string>> => getTimerPromise(50, new FailedResult("error 1"));
    const opFailB = (): Promise<Result<boolean, number>> => getTimerPromise(20, new FailedResult(3));


    it("when one or more failures exist returns a failure containing the first one found", async () => {
        const res = await PromiseResult.allObj({
            op1: opSuccessA(),
            op2: opFailA(),
            op3: opSuccessB(),
            op4: opFailB()
        });

        expect(res.failed).toBeTrue();
        expect(res.error).toEqual(3);
    });


    it("when all succeed returns an object of named sucess values", async () => {
        const res = await PromiseResult.allObj({
            op1: opSuccessA(),
            op2: opSuccessB()
        });

        expect(res.succeeded).toBeTrue();
        expect(res.value).toEqual({
            op1: "hello",
            op2: ["one", "two", "three"]
        });
    });


});


describe("allM()", () => {
    it("when all are successful, the returned promise resolves with a Result containing an array of all the successful values", async () => {
        const op1 = () => getTimerPromise(25, new SucceededResult(25));
        const op2 = () => getTimerPromise(50, new SucceededResult(50));
        const op3 = () => getTimerPromise(75, new SucceededResult(75));

        const result = await PromiseResult.allM(op1(), op2(), op3());
        expect(result.succeeded).toBeTruthy();
        expect(result.value).toEqual([25, 50, 75]);
    });


    it("works with an input array of one element", async () => {
        const result = await PromiseResult.allM(
            getTimerPromise(25, new SucceededResult(25))
        );
        expect(result.succeeded).toBeTruthy();
        expect(result.value).toEqual([25]);
    });


    it("when one result fails, the returned promise resolves with a Result containing the index of the item that failed and its error", async () => {
        const op1 = () => getTimerPromise(25, new SucceededResult(25));
        const op2 = () => getTimerPromise(50, new FailedResult("Error 1"));
        const op3 = () => getTimerPromise(75, new SucceededResult(75));

        const result = await PromiseResult.allM(op1(), op2(), op3());
        expect(result.failed).toBeTruthy();
        expect(result.error!.index).toEqual(1);
        expect(result.error!.item).toEqual("Error 1");
    });


    it("when one result fails, the returned promise resolves *immediately* with the failure", async () => {
        const op1 = () => getTimerPromise(25, new SucceededResult(25));
        const op2 = () => getTimerPromise(50, new FailedResult("Error 1"));
        const op3 = () => getTimerPromise(75, new SucceededResult(75));

        const startTime = Date.now();
        const __result = await PromiseResult.allM(op1(), op2(), op3());
        const resolveTime = Date.now();
        expect(resolveTime - startTime).toBeGreaterThanOrEqual(50);
        expect(resolveTime - startTime).toBeLessThanOrEqual(70);
    });
});


describe("allArrayA()", () => {

    it("when input array is empty, returns a successful result with an empty array", async () => {

        const res = await PromiseResult.allArrayA([]);
        expect(res.succeeded).toBeTrue();
        if (res.succeeded) {
            expect(res.value.length).toEqual(0);
        }
    });


    it("when there are failures, returns IIndexedItems referencing each failure", async () => {
        const start = Date.now();

        const res = await PromiseResult.allArrayA([
            getTimerPromise(5, new SucceededResult(0)),
            getTimerPromise(10, new FailedResult("error 1")),
            getTimerPromise(15, new SucceededResult(2)),
            getTimerPromise(20, new FailedResult("error 3")),
            getTimerPromise(25, new SucceededResult(4)),
            getTimerPromise(30, new FailedResult("error 5")),
            getTimerPromise(35, new SucceededResult(6))
        ]);

        const end = Date.now();

        expect(res.failed).toBeTrue();
        expect(res.error).toEqual([
            { index: 1, item: "error 1"},
            { index: 3, item: "error 3"},
            { index: 5, item: "error 5"}
        ]);
        expect(end - start).toBeGreaterThanOrEqual(35);
    });


    it("when all are successful, returns successful Result wrapping all values", async () => {
        const res = await PromiseResult.allArrayA([
            getTimerPromise(5, new SucceededResult(0)),
            getTimerPromise(10, new SucceededResult(1)),
            getTimerPromise(15, new SucceededResult(2)),
            getTimerPromise(20, new SucceededResult(3)),
            getTimerPromise(25, new SucceededResult(4)),
            getTimerPromise(30, new SucceededResult(5)),
            getTimerPromise(35, new SucceededResult(6))
        ]);

        expect(res.succeeded).toBeTrue();
        expect(res.value).toEqual([0, 1, 2, 3, 4, 5, 6]);
    });

});


describe("allArrayM()", () => {

    it("when the input array is empty, returns a successful result with an empty array", async () => {
        const res = await PromiseResult.allArrayM([]);

        expect(res.succeeded).toBeTrue();
        if (res.succeeded) {
            expect(res.value.length).toEqual(0);
        }
    });


    it("resolves as soon as possible with the first failure", async () => {

        const start = Date.now();

        const res = await PromiseResult.allArrayM([
            getTimerPromise(5, new SucceededResult(1)),
            getTimerPromise(15, new FailedResult("error 1")),
            getTimerPromise(40, new SucceededResult(2)),
            getTimerPromise(50, new SucceededResult(3)),
            getTimerPromise(60, new FailedResult("error 2"))
        ]);

        const end = Date.now();
        const delta = end - start;
        expect(delta).toBeGreaterThanOrEqual(10);
        expect(delta).toBeLessThanOrEqual(35);  // Saw this get as high as 27
        expect(res.failed).toBeTrue();
        expect(res.error!.index).toEqual(1);
        expect(res.error!.item).toEqual("error 1");
    });


    it("when all are successful, returns successful Result wrapping all values", async () => {
        const start = Date.now();
        const res = await PromiseResult.allArrayM([
            getTimerPromise(5, new SucceededResult(1)),
            getTimerPromise(10, new SucceededResult(2)),
            getTimerPromise(15, new SucceededResult(3))
        ]);

        const end = Date.now();
        expect(end - start).toBeGreaterThanOrEqual(0.9 * 15);
        expect(res.succeeded).toBeTrue();
        expect(res.value).toEqual([1, 2, 3]);
    });

});


describe("bind()", () => {

    it("allows the input to be a Result<>", async () => {
        const fn = (x: number) => new SucceededResult(x + 1);
        const res = await PromiseResult.bind(fn, new SucceededResult(5));
        expect(res.succeeded).toBeTrue();
        expect(res.value).toEqual(6);
    });


    it("allows the input to be a Promise<Result<>>", async () => {
        const fn = (x: number) => Promise.resolve(new SucceededResult(x + 1));
        const res = await PromiseResult.bind(fn, Promise.resolve(new SucceededResult(5)));
        expect(res.succeeded).toBeTrue();
        expect(res.value).toEqual(6);
    });


    it("does not invoke the function if the input is a failure", async () => {
        let numInvocations = 0;
        const fn = (x: number) => {
            numInvocations++;
            return Promise.resolve(new SucceededResult(x + 1));
        };

        const res = await PromiseResult.bind(fn, new FailedResult("error"));
        expect(res.failed).toBeTrue();
        expect(numInvocations).toEqual(0);
    });


    it("works well in a pipeAsync()", async () => {
        const fn = (x: number) => Promise.resolve(new SucceededResult(x + 1));
        const res =
            await pipeAsync(Promise.resolve(new SucceededResult(5)))
            .pipe((res) => PromiseResult.bind(fn, res))
            .pipe((res) => PromiseResult.bind(fn, res))
            .pipe((res) => PromiseResult.bind(fn, res))
            .end();
        expect(res.succeeded).toBeTrue();
        expect(res.value).toEqual(8);
    });


});


describe("gate()", () => {

    it("when the input is a failed Result it is passed through", async () => {
        let numInvocations = 0;
        const gateFn = async (x: number) => {
            await Promise.resolve(0);
            numInvocations++;
            return x % 2 === 0 ?
                new SucceededResult(x * 10) :
                new FailedResult("odd");
        };

        const resInitial = new FailedResult("initial error");
        const res = await PromiseResult.gate(gateFn, resInitial);
        expect(res.failed).toBeTrue();
        expect(res.error).toEqual("initial error");
        expect(numInvocations).toEqual(0);
    });


    it("when the input is a successful result the function is invoked", async () => {
        let numInvocations = 0;
        const gateFn = async (x: number) => {
            await Promise.resolve(0);
            numInvocations++;
            return x % 2 === 0 ?
                new SucceededResult(x * 10) :
                new FailedResult("odd");
        };

        const resInitial = new SucceededResult(5);
        const __res = await PromiseResult.gate(gateFn, resInitial);
        expect(numInvocations).toEqual(1);
    });


    it("when the input is successful and the gate function succeeds the original input is returned", async () => {
        let numInvocations = 0;
        const gateFn = async (x: number) => {
            await Promise.resolve(0);
            numInvocations++;
            return x % 2 === 0 ?
                new SucceededResult(x * 10) :
                new FailedResult("odd");
        };

        const resInitial = new SucceededResult(2);
        const res = await PromiseResult.gate(gateFn, resInitial);
        expect(res.succeeded).toBeTrue();
        expect(res.value).toEqual(2);
        expect(numInvocations).toEqual(1);
    });


    it("when the input is successful and the gate function fails the failure is returned", async () => {
        let numInvocations = 0;
        const gateFn = async (x: number) => {
            await Promise.resolve(0);
            numInvocations++;
            return x % 2 === 0 ?
                new SucceededResult(x * 10) :
                new FailedResult("odd");
        };

        const resInitial = new SucceededResult(3);
        const res = await PromiseResult.gate(gateFn, resInitial);
        expect(res.failed).toBeTrue();
        expect(res.error).toEqual("odd");
        expect(numInvocations).toEqual(1);
    });
});


describe("mapError()", () => {

    it("allows the input to be a Result<>", async () => {
        const fn = (x: number) => Promise.resolve(x + 1);
        const res = await PromiseResult.mapError(fn, new FailedResult(6));
        expect(res.failed).toBeTrue();
        expect(res.error).toEqual(7);
    });


    it("allows the input to be a Promise<Result<>>", async () => {
        const fn = (x: number) => Promise.resolve(x + 1);
        const res = await PromiseResult.mapError(fn, Promise.resolve(new FailedResult(6)));
        expect(res.failed).toBeTrue();
        expect(res.error).toEqual(7);
    });


    it("does not invoke the function if the input is successful", async () => {
        let numInvocations = 0;
        const fn = (x: number) => {
            numInvocations++;
            return Promise.resolve(x + 1);
        };

        const res = await PromiseResult.mapError(fn, new SucceededResult(3));
        expect(res.succeeded).toBeTrue();
        expect(numInvocations).toEqual(0);
    });


    it("works well with pipeAsync()", async () => {
        const fn = (x: number) => Promise.resolve(x + 1);
        const res =
            await pipeAsync(Promise.resolve(new FailedResult(5)))
            .pipe((res) => PromiseResult.mapError(fn, res))
            .pipe((res) => PromiseResult.mapError(fn, res))
            .pipe((res) => PromiseResult.mapError(fn, res))
            .end();
        expect(res.failed).toBeTrue();
        expect(res.error).toEqual(8);
    });

});


describe("mapSuccess()", () => {

    it("allows the input to be a Result<>", async () => {
        const fn = (x: number) => Promise.resolve(x + 1);
        const res = await PromiseResult.mapSuccess(fn, new SucceededResult(6));
        expect(res.succeeded).toBeTrue();
        expect(res.value).toEqual(7);
    });


    it("allows the input to be a Promise<Result<>>", async () => {
        const fn = (x: number) => Promise.resolve(x + 1);
        const res = await PromiseResult.mapSuccess(fn, Promise.resolve(new SucceededResult(6)));
        expect(res.succeeded).toBeTrue();
        expect(res.value).toEqual(7);
    });


    it("does not invoke the function if the input is a failure", async () => {
        let numInvocations = 0;
        const fn = (x: number) => {
            numInvocations++;
            return Promise.resolve(x + 1);
        };

        const res = await PromiseResult.mapSuccess(fn, new FailedResult("error"));
        expect(res.failed).toBeTrue();
        expect(numInvocations).toEqual(0);
    });


    it("works well with pipeAsync()", async () => {
        const fn = (x: number) => Promise.resolve(x + 1);
        const res =
            await pipeAsync(Promise.resolve(new SucceededResult(5)))
            .pipe((res) => PromiseResult.mapSuccess(fn, res))
            .pipe((res) => PromiseResult.mapSuccess(fn, res))
            .pipe((res) => PromiseResult.mapSuccess(fn, res))
            .end();
        expect(res.succeeded).toBeTrue();
        expect(res.value).toEqual(8);
    });

});


describe("tapError()", () => {

    it("allows the input to be a Result", async () => {
        const fn = async () => Promise.resolve(undefined);
        const res = await PromiseResult.tapError(fn, new SucceededResult(3));
        expect(res.succeeded).toBeTrue();
    });


    it("calls the function when the input Result is a failure", async () => {
        let numInvocations = 0;
        function tapFn(err: string) {
            numInvocations++;
            return Promise.resolve("tapFn() return value");
        }

        await pipeAsync(new FailedResult("error message") as Result<number, string>)
        .pipe((res) => PromiseResult.tapError(tapFn, res))
        .end();

        expect(numInvocations).toEqual(1);
    });


    it("does not call the function when the input Result is successful", async () => {
        let numInvocations = 0;
        function tapFn(err: string) {
            numInvocations++;
            return Promise.resolve("tapFn() return value");
        }

        await pipeAsync(new SucceededResult(1) as Result<number, string>)
        .pipe((res) => PromiseResult.tapError(tapFn, res))
        .end();

        expect(numInvocations).toEqual(0);
    });


    it("returns the original Result", async () => {
        let numInvocations = 0;
        function tapFn(err: string) {
            numInvocations++;
            return Promise.resolve("tapFn() return value");
        }

        const actual =
            await pipeAsync(new FailedResult("error message") as Result<number, string>)
            .pipe((res) => PromiseResult.tapError(tapFn, res))
            .end();

        expect(numInvocations).toEqual(1);
        expect(actual).toEqual(new FailedResult("error message"));
    });
});


describe("tapSuccess()", () => {


    it("allows the input to be a Result", async () => {
        const fn = async () => Promise.resolve(undefined);
        const res = await PromiseResult.tapSuccess(fn, new SucceededResult(3));
        expect(res.succeeded).toBeTrue();
    });


    it("does not call the function when the input Result is a failure", async () => {
        let numInvocations = 0;
        function tapFn(num: number) {
            numInvocations++;
            return Promise.resolve("tap func return value");
        }

        await pipeAsync(new FailedResult("error message") as Result<number, string>)
        .pipe((res) => PromiseResult.tapSuccess(tapFn, res))
        .end();

        expect(numInvocations).toEqual(0);
    });


    it("calls the function when the input Result is successful", async () => {
        let numInvocations = 0;
        function tapFn(num: number) {
            numInvocations++;
            return Promise.resolve("tap func return value");
        }

        await pipeAsync(new SucceededResult(3) as Result<number, string>)
        .pipe((res) => PromiseResult.tapSuccess(tapFn, res))
        .end();

        expect(numInvocations).toEqual(1);
    });


    it("returns the original Result", async () => {
        let numInvocations = 0;
        function tapFn(num: number) {
            numInvocations++;
            return Promise.resolve("tap func return value");
        }

        const actual =
            await pipeAsync(new SucceededResult(3) as Result<number, string>)
            .pipe((res) => PromiseResult.tapSuccess(tapFn, res))
            .end();

        expect(numInvocations).toEqual(1);
        expect(actual).toEqual(new SucceededResult(3));
    });

});


describe("forceResult()", () => {

    it("When the Promise resolves with a successful Result it is returned", async () => {
        const pr = Promise.resolve(new SucceededResult(21));
        const res = await PromiseResult.forceResult(pr);
        expect(res.succeeded).toBeTrue();
        expect(res.value).toEqual(21);
    });


    it("when the Promise resolves with a failure Result it is returned", async () => {
        const pr = Promise.resolve(new FailedResult("Error message 37"));
        const res = await PromiseResult.forceResult(pr);
        expect(res.failed).toBeTrue();
        expect(res.error).toEqual("Error message 37");
    });


    it("when the Promise rejects a failure Result containing a string is returned", async () => {
        const pr = Promise.reject("error 34");
        const res = await PromiseResult.forceResult(pr);
        expect(res.failed).toBeTrue();
        expect(res.error).toEqual("error 34");
    });


});
